Workbook

Sheet Page de Garde
D2: Lancement Affaire - Bureau d'Etudes
D3: DOMAINE D'APPLICATION | F3: NATURE | G3: N° D'ORDRE | H3: VERSION | I3: NB DE PAGES
D4: 2025-AF283 | F4: LBE | G4: 01 | H4: =IF(B21="","v0",IF(B22="","v1",IF(B23="","v2",IF(B25="","v3","")))) -> v0 | I4: =+IF(D23="",IF(D22="",IF(D21="",D20,D21),D22),D23) -> 0
B6: Code client | C6: =VLOOKUP($D$4,#REF!,3,FALSE) -> #REF! | F6: code resp | G6: =VLOOKUP($D$4,#REF!,4,FALSE) -> #REF!
B8: N° Affaire | C8: =IF(D4="","",D4) -> 2025-AF283 | E8: Client | F8: STORENGY
B10: Intitulé | C10: Projet ORMO - Lot 401
B12: Responsable Affaire ARTIS | C12: LLE
B14: Révisions du document
B15: Version | C15: Date | D15: Modification | I15: Initiales
B16: 0 | C16: 46112 | D16: CREATION DU FICHIER | I16: TG
B23: Interlocuteur Client 1
B24: NOM - Prénom | D24: Poste | F24: N° Téléphone | H24: Adresse mail
B25: Mike ROBERT | D25: Ingénieur Mécanique | F25: 06.58.29.93.87 | H25: mike.robert@natrangroupe.com
B27: Interlocuteur Client 2 (si nécessaire)
B28: NOM - Prénom | D28: Poste | F28: N° Téléphone | H28: Adresse mail
B32: Interlocuteur ARTIS
B33: Nom - Prénom | C33: Fonction | D33: Adresse | F33: Téléphone fixe | G33: Téléphone mobile | H33: E-mail

Sheet Actions - Liste des livrables
D2: Lancement Affaire - Bureau d'Etudes
D3: DOMAINE D'APPLICATION | E3: NATURE | F3: N° D'ORDRE | G3: VERSION
D4: ='Page de Garde'!D4 -> 2025-AF283 | E4: LBE | F4: ='Page de Garde'!G4 -> 01 | G4: ='Page de Garde'!H4 -> v0
C6: ACTIONS BUREAU D'ETUDES
C7: LIVRABLES CLIENT
C8: DOCUMENTS A PRODUIRE | M8: LISTE A COPIER SI NECESSAIRE
C10: Elément | E10: COMMENTAIRES | I10: SELECTIONNER | M10: Elément
B11: =VLOOKUP(1,$L$11:$L$31,1,FALSE) -> 1 | C11: =VLOOKUP(1,L11:M46,2,FALSE) -> Nomenclature | I11: x | J11: 1 | K11: =+IF(I11="","",J11) -> 1 | L11: =IF(I11="","",RANK(K11,$K$11:$K$46,1)) -> 1 | M11: Nomenclature
B12: =IF(MAX($L$11:$L$46)<=1,"",VLOOKUP(B11+1,$L$11:$M$46,1,FALSE)) -> 2 | C12: =IF(MAX($L$11:$L$46)<=1,"",VLOOKUP(B11+1,$L$11:$M$46,2,FALSE)) -> Plans isométriques manuel | I12: x | J12: 2 | K12: =+IF(I12="","",J12) -> 2 | L12: =IF(I12="","",RANK(K12,$K$11:$K$46,1)) -> 2 | M12: Plans isométriques manuel
B13: =IF(MAX($L$11:$L$46)<=2,"",VLOOKUP(B12+1,$L$11:$M$46,1,FALSE)) -> 3 | C13: =IF(MAX($L$11:$L$46)<=2,"",VLOOKUP(B12+1,$L$11:$M$46,2,FALSE)) -> Résa 80% | I13: x | J13: 3 | K13: =+IF(I13="","",J13) -> 3 | L13: =IF(I13="","",RANK(K13,$K$11:$K$46,1)) -> 3 | M13: Résa 80%
B14: =IF(MAX($L$11:$L$46)<=3,"",VLOOKUP(B13+1,$L$11:$M$46,1,FALSE)) -> 4 | C14: =IF(MAX($L$11:$L$46)<=3,"",VLOOKUP(B13+1,$L$11:$M$46,2,FALSE)) -> Plans 3D | I14: x | J14: 4 | K14: =+IF(I14="","",J14) -> 4 | L14: =IF(I14="","",RANK(K14,$K$11:$K$46,1)) -> 4 | M14: Plans 3D
B15: =IF(MAX($L$11:$L$46)<=4,"",VLOOKUP(B14+1,$L$11:$M$46,1,FALSE)) -> 5 | C15: =IF(MAX($L$11:$L$46)<=4,"",VLOOKUP(B14+1,$L$11:$M$46,2,FALSE)) -> Plans TUT | I15: x | J15: 5 | K15: =+IF(I15="","",J15) -> 5 | L15: =IF(I15="","",RANK(K15,$K$11:$K$46,1)) -> 5 | M15: Plans TUT
B16: =IF(MAX($L$11:$L$46)<=5,"",VLOOKUP(B15+1,$L$11:$M$46,1,FALSE)) -> 6 | C16: =IF(MAX($L$11:$L$46)<=5,"",VLOOKUP(B15+1,$L$11:$M$46,2,FALSE)) -> Résa 100% | I16: x | J16: 6 | K16: =+IF(I16="","",J16) -> 6 | L16: =IF(I16="","",RANK(K16,$K$11:$K$46,1)) -> 6 | M16: Résa 100%
B17: =IF(MAX($L$11:$L$46)<=6,"",VLOOKUP(B16+1,$L$11:$M$46,1,FALSE)) -> 7 | C17: =IF(MAX($L$11:$L$46)<=6,"",VLOOKUP(B16+1,$L$11:$M$46,2,FALSE)) -> Plans isométriques - Repérage pièces | I17: x | J17: 7 | K17: =+IF(I17="","",J17) -> 7 | L17: =IF(I17="","",RANK(K17,$K$11:$K$46,1)) -> 7 | M17: Plans isométriques - Repérage pièces
B18: =IF(MAX($L$11:$L$46)<=7,"",VLOOKUP(B17+1,$L$11:$M$46,1,FALSE)) -> 8 | C18: =IF(MAX($L$11:$L$46)<=7,"",VLOOKUP(B17+1,$L$11:$M$46,2,FALSE)) -> Plans isométriques - Repérage soudures | I18: x | J18: 8 | K18: =+IF(I18="","",J18) -> 8 | L18: =IF(I18="","",RANK(K18,$K$11:$K$46,1)) -> 8 | M18: Plans isométriques - Repérage soudures
B19: =IF(MAX($L$11:$L$46)<=8,"",VLOOKUP(B18+1,$L$11:$M$46,1,FALSE)) -> 9 | C19: =IF(MAX($L$11:$L$46)<=8,"",VLOOKUP(B18+1,$L$11:$M$46,2,FALSE)) -> Tableau de débits | I19: x | J19: 9 | K19: =+IF(I19="","",J19) -> 9 | L19: =IF(I19="","",RANK(K19,$K$11:$K$46,1)) -> 9 | M19: Tableau de débits
B20: =IF(MAX($L$11:$L$46)<=9,"",VLOOKUP(B19+1,$L$11:$M$46,1,FALSE)) -> 10 | C20: =IF(MAX($L$11:$L$46)<=9,"",VLOOKUP(B19+1,$L$11:$M$46,2,FALSE)) -> Plans GC | I20: x | J20: 10 | K20: =+IF(I20="","",J20) -> 10 | L20: =IF(I20="","",RANK(K20,$K$11:$K$46,1)) -> 10 | M20: Plans GC
B21: =IF(MAX($L$11:$L$46)<=10,"",VLOOKUP(B20+1,$L$11:$M$46,1,FALSE)) -> 11 | C21: =IF(MAX($L$11:$L$46)<=10,"",VLOOKUP(B20+1,$L$11:$M$46,2,FALSE)) -> Plans de manchettes délardées | E21: Raccordement sur existant | I21: x | J21: 11 | K21: =+IF(I21="","",J21) -> 11 | L21: =IF(I21="","",RANK(K21,$K$11:$K$46,1)) -> 11 | M21: Plans de manchettes délardées
B22: =IF(MAX($L$11:$L$46)<=11,"",VLOOKUP(B21+1,$L$11:$M$46,1,FALSE)) -> 12 | C22: =IF(MAX($L$11:$L$46)<=11,"",VLOOKUP(B21+1,$L$11:$M$46,2,FALSE)) -> Plans de châssis | E22: Supports tuyauteries | I22: x | J22: 12 | K22: =+IF(I22="","",J22) -> 12 | L22: =IF(I22="","",RANK(K22,$K$11:$K$46,1)) -> 12 | M22: Plans de châssis
B23: =IF(MAX($L$11:$L$46)<=12,"",VLOOKUP(B22+1,$L$11:$M$46,1,FALSE)) -> 13 | C23: =IF(MAX($L$11:$L$46)<=12,"",VLOOKUP(B22+1,$L$11:$M$46,2,FALSE)) -> Plans de terrassement | I23: x | J23: 13 | K23: =+IF(I23="","",J23) -> 13 | L23: =IF(I23="","",RANK(K23,$K$11:$K$46,1)) -> 13 | M23: Plans de terrassement
B24: =IF(MAX($L$11:$L$46)<=13,"",VLOOKUP(B23+1,$L$11:$M$46,1,FALSE)) -> 14 | C24: =IF(MAX($L$11:$L$46)<=13,"",VLOOKUP(B23+1,$L$11:$M$46,2,FALSE)) -> Plans de montage d'épreuve/séchage | J24: 14 | K24: =+IF(I24="","",J24) | L24: =IF(I24="","",RANK(K24,$K$11:$K$46,1)) | M24: Plans d'installation chantier / Base vie
B25: =IF(MAX($L$11:$L$46)<=14,"",VLOOKUP(B24+1,$L$11:$M$46,1,FALSE)) -> 15 | C25: =IF(MAX($L$11:$L$46)<=14,"",VLOOKUP(B24+1,$L$11:$M$46,2,FALSE)) -> Plans isométriques - Repérage brides et appareils | I25: x | J25: 15 | K25: =+IF(I25="","",J25) -> 15 | L25: =IF(I25="","",RANK(K25,$K$11:$K$46,1)) -> 14 | M25: Plans de montage d'épreuve/séchage
B26: =IF(MAX($L$11:$L$46)<=15,"",VLOOKUP(B25+1,$L$11:$M$46,1,FALSE)) -> 16 | C26: =IF(MAX($L$11:$L$46)<=15,"",VLOOKUP(B25+1,$L$11:$M$46,2,FALSE)) -> Plans de sertissage | I26: x | J26: 16 | K26: =+IF(I26="","",J26) -> 16 | L26: =IF(I26="","",RANK(K26,$K$11:$K$46,1)) -> 15 | M26: Plans isométriques - Repérage brides et appareils
B27: =IF(MAX($L$11:$L$46)<=16,"",VLOOKUP(B26+1,$L$11:$M$46,1,FALSE)) -> 17 | C27: =IF(MAX($L$11:$L$46)<=16,"",VLOOKUP(B26+1,$L$11:$M$46,2,FALSE)) -> Plans Levage | I27: x | J27: 17 | K27: =+IF(I27="","",J27) -> 17 | L27: =IF(I27="","",RANK(K27,$K$11:$K$46,1)) -> 16 | M27: Plans de sertissage
B28: =IF(MAX($L$11:$L$46)<=17,"",VLOOKUP(B27+1,$L$11:$M$46,1,FALSE)) -> 18 | C28: =IF(MAX($L$11:$L$46)<=17,"",VLOOKUP(B27+1,$L$11:$M$46,2,FALSE)) -> Montage sur site | I28: x | J28: 18 | K28: =+IF(I28="","",J28) -> 18 | L28: =IF(I28="","",RANK(K28,$K$11:$K$46,1)) -> 17 | M28: Plans Levage
B29: =IF(MAX($L$11:$L$46)<=18,"",VLOOKUP(B28+1,$L$11:$M$46,1,FALSE)) -> 19 | C29: =IF(MAX($L$11:$L$46)<=18,"",VLOOKUP(B28+1,$L$11:$M$46,2,FALSE)) -> Maquette 3D | I29: x | J29: 19 | K29: =+IF(I29="","",J29) -> 19 | L29: =IF(I29="","",RANK(K29,$K$11:$K$46,1)) -> 18 | M29: Montage sur site
B30: =IF(MAX($L$11:$L$46)<=19,"",VLOOKUP(B29+1,$L$11:$M$46,1,FALSE)) -> 20 | C30: =IF(MAX($L$11:$L$46)<=19,"",VLOOKUP(B29+1,$L$11:$M$46,2,FALSE)) -> Spécifique (à préciser) | J30: 20 | K30: =+IF(I30="","",J30) | L30: =IF(I30="","",RANK(K30,$K$11:$K$46,1)) | M30: Plans enrobage / Peinture
B31: =IF(MAX($L$11:$L$46)<=20,"",VLOOKUP(B30+1,$L$11:$M$46,1,FALSE)) -> 21 | C31: =IF(MAX($L$11:$L$46)<=20,"",VLOOKUP(B30+1,$L$11:$M$46,2,FALSE)) -> Cahier de soudage avec validation pré-soudage | I31: x | J31: 21 | K31: =+IF(I31="","",J31) -> 21 | L31: =IF(I31="","",RANK(K31,$K$11:$K$46,1)) -> 19 | M31: Maquette 3D
B32: =IF(MAX($L$11:$L$46)<=21,"",VLOOKUP(B31+1,$L$11:$M$46,1,FALSE)) -> 22 | C32: =IF(MAX($L$11:$L$46)<=21,"",VLOOKUP(B31+1,$L$11:$M$46,2,FALSE)) -> Dossier d'épreuve selon DESP 2014/68/UE | J32: 22 | K32: =+IF(I32="","",J32) | L32: =IF(I32="","",RANK(K32,$K$11:$K$46,1)) | M32: GDER TUT
B33: =IF(MAX($L$11:$L$46)<=22,"",VLOOKUP(B32+1,$L$11:$M$46,1,FALSE)) -> 23 | C33: =IF(MAX($L$11:$L$46)<=22,"",VLOOKUP(B32+1,$L$11:$M$46,2,FALSE)) -> Dossier de Fabrication selon Art.4.3 | J33: 23 | K33: =+IF(I33="","",J33) | L33: =IF(I33="","",RANK(K33,$K$11:$K$46,1)) | M33: GDER GCT
B34: =IF(MAX($L$11:$L$46)<=23,"",VLOOKUP(B33+1,$L$11:$M$46,1,FALSE)) -> 24 | C34: =IF(MAX($L$11:$L$46)<=23,"",VLOOKUP(B33+1,$L$11:$M$46,2,FALSE)) -> Relevé Epaisseur Manchette délardée | J34: 24 | K34: =+IF(I34="","",J34) | L34: =IF(I34="","",RANK(K34,$K$11:$K$46,1)) | M34: GDER DREAL
B35: =IF(MAX($L$11:$L$46)<=24,"",VLOOKUP(B34+1,$L$11:$M$46,1,FALSE)) -> 25 | C35: =IF(MAX($L$11:$L$46)<=24,"",VLOOKUP(B34+1,$L$11:$M$46,2,FALSE)) -> PV Cintrage | I35: x | J35: 25 | K35: =+IF(I35="","",J35) -> 25 | L35: =IF(I35="","",RANK(K35,$K$11:$K$46,1)) -> 20 | M35: Spécifique (à préciser)
B36: =IF(MAX($L$11:$L$46)<=25,"",VLOOKUP(B35+1,$L$11:$M$46,1,FALSE)) -> 26 | C36: =IF(MAX($L$11:$L$46)<=25,"",VLOOKUP(B35+1,$L$11:$M$46,2,FALSE)) -> Carnet de soudures | J36: 26 | K36: =+IF(I36="","",J36) | L36: =IF(I36="","",RANK(K36,$K$11:$K$46,1))
B37: =IF(MAX($L$11:$L$46)<=26,"",VLOOKUP(B36+1,$L$11:$M$46,1,FALSE)) -> 27 | C37: =IF(MAX($L$11:$L$46)<=26,"",VLOOKUP(B36+1,$L$11:$M$46,2,FALSE)) -> Dossier de fin d'affaire | I37: x | J37: 27 | K37: =+IF(I37="","",J37) -> 27 | L37: =IF(I37="","",RANK(K37,$K$11:$K$46,1)) -> 21 | M37: Cahier de soudage avec validation pré-soudage
B38: =IF(MAX($L$11:$L$46)<=27,"",VLOOKUP(B37+1,$L$11:$M$46,1,FALSE)) | C38: =IF(MAX($L$11:$L$46)<=27,"",VLOOKUP(B37+1,$L$11:$M$46,2,FALSE)) | J38: 28 | K38: =+IF(I38="","",J38) | L38: =IF(I38="","",RANK(K38,$K$11:$K$46,1)) | M38: DMOS / QMOS /QS
B39: =IF(MAX($L$11:$L$46)<=28,"",VLOOKUP(B38+1,$L$11:$M$46,1,FALSE)) | C39: =IF(MAX($L$11:$L$46)<=28,"",VLOOKUP(B38+1,$L$11:$M$46,2,FALSE)) | I39: x | J39: 29 | K39: =+IF(I39="","",J39) -> 29 | L39: =IF(I39="","",RANK(K39,$K$11:$K$46,1)) -> 22 | M39: Dossier d'épreuve selon DESP 2014/68/UE
B40: =IF(MAX($L$11:$L$46)<=29,"",VLOOKUP(B39+1,$L$11:$M$46,1,FALSE)) | C40: =IF(MAX($L$11:$L$46)<=29,"",VLOOKUP(B39+1,$L$11:$M$46,2,FALSE)) | J40: 30 | K40: =+IF(I40="","",J40) | L40: =IF(I40="","",RANK(K40,$K$11:$K$46,1)) | M40: Dossier d'épreuve selon A.M du 05/03/2014
B41: =IF(MAX($L$11:$L$46)<=30,"",VLOOKUP(B40+1,$L$11:$M$46,1,FALSE)) | C41: =IF(MAX($L$11:$L$46)<=30,"",VLOOKUP(B40+1,$L$11:$M$46,2,FALSE)) | I41: x | J41: 31 | K41: =+IF(I41="","",J41) -> 31 | L41: =IF(I41="","",RANK(K41,$K$11:$K$46,1)) -> 23 | M41: Dossier de Fabrication selon Art.4.3
B42: =IF(MAX($L$11:$L$46)<=31,"",VLOOKUP(B41+1,$L$11:$M$46,1,FALSE)) | C42: =IF(MAX($L$11:$L$46)<=31,"",VLOOKUP(B41+1,$L$11:$M$46,2,FALSE)) | I42: x | J42: 32 | K42: =+IF(I42="","",J42) -> 32 | L42: =IF(I42="","",RANK(K42,$K$11:$K$46,1)) -> 24 | M42: Relevé Epaisseur Manchette délardée
B43: =IF(MAX($L$11:$L$46)<=32,"",VLOOKUP(B42+1,$L$11:$M$46,1,FALSE)) | C43: =IF(MAX($L$11:$L$46)<=32,"",VLOOKUP(B42+1,$L$11:$M$46,2,FALSE)) | I43: x | J43: 33 | K43: =+IF(I43="","",J43) -> 33 | L43: =IF(I43="","",RANK(K43,$K$11:$K$46,1)) -> 25 | M43: PV Cintrage
...

Sheet Liste des lignes
G2: Lancement Affaire - Bureau d'Etudes
G3: DOMAINE D'APPLICATION | H3: NATURE | I3: N° D'ORDRE | J3: VERSION
G4: ='Page de Garde'!$D$4 -> 2025-AF283 | H4: LBE | I4: ='Page de Garde'!$G$4 -> 01 | J4: ='Page de Garde'!$H$4 -> v0
B6: LISTE DES LIGNES
B9: Information : 1 TYPE DE LIGNE = 1 Dossier EH | L9: CARACTERISTIQUES DES LIGNES
B10: N° | C10: NOM DE LA LIGNE | E10: QUANTITE | G10: SENS DU FLUIDE | L10: CONDITIONS OPERATOIRES | V10: INSPECTION /CONDITIONS EH | AD10: CONTROLES | AL10: Autres
G11: VENANT DE | I11: ALLANT VERS | L11: FLUIDE | M11: DN MAX | N11: MATIERE | O11: TYPE DE TUBE | P11: EP ou SCH | Q11: SERIE RACCORD | R11: ENTERRE ou AERIEN | S11: T°C Min | T11: T°C Max | U11: LONGUEUR | V11: PC PS | W11: PT | X11: FLUIDE EH | Y11: REGLEMENTATION | Z11: CAT. EMP. (Transport) | AA11: CAT. RISQUE (DESP) | AB11: CAT. CONSTRUCTION (DESP) | AC11: MODULE EVALUATION (DESP) | AD11: PLAQUE CE | AE11: %VT (BW-SW-FW) | AF11: %RT (BW) | AG11: %RT (SW) | AH11: %PT (BW) | AI11: %PT (SW) | AJ11: %PT (FW) | AK11: %UT (Avant Perçage) | AL11: RAL PEINTURE | AM11: SPECIFICATION PEINTURE | AN11: TYPE ENROBAGE | AO11: SPECIFICATION ENROBAGE | AP11: PRESCRIPTION TUBING | AQ11: TYPE DE SUPPORTAGE | AR11: COMMENTAIRES | AX11: Gaz Naturel | AY11: Codeti 2013 Rev.11/16 | AZ11: C | BA11: C | BB11: TRAPIL
B12: =1 -> 1 | C12: Event filtre | E12: 1 | L12: THT (gaz) Azote (gaz) | M12: 50 | N12: 20SU20 | O12: 20SU20 | P12: 20SU20 | Q12: 20SU20 | R12: Aérien | S12: -20 | T12: 60 | U12: - | V12: 18 3 | W12: 4.5 | X12: Eau | Y12: DESP 2014/68/UE Codeti 2023 Div.1 S-SG-TU-0615 | AA12: I | AB12: B2 | AC12: A | AD12: OUI | AE12: 1 | AF12: 0.05 | AG12: 0.05 | AH12: 0.2 | AI12: 0.2 | AJ12: 0.05 | AL12: - | AM12: - | AN12: - | AO12: - | AP12: - | AQ12: - | AX12: Eau Chaude | AY12: A.M. du 05/03/2014 | AZ12: B | BA12: B2 | BB12: Air Liquide
B13: 2 | C13: Pare-Flamme Filtre | E13: 1 | Y13: DESP 2014/68/UE Codeti 2023 Div.1 S-SG-TU-0615 | AX13: AFGAS | AY13: CODAP 2015 | AZ13: A | BA13: B1 | BB13: ACQPA C3
B14: 3 | C14: Pare-Flamme Event | E14: 1 | Y14: DESP 2014/68/UE Codeti 2023 Div.1 S-SG-TU-0615 | AX14: JET-A1 | BA14: A | BB14: ACQPA C4
B15: 4 | C15: Déverseur soupape C5 | E15: 1 | Y15: DESP 2014/68/UE Codeti 2023 Div.1 S-SG-TU-0615 | AX15: Azote
B16: 5 | C16: Déverseur RBS Flottant C5 | E16: 1 | Y16: DESP 2014/68/UE Codeti 2023 Div.1 S-SG-TU-0615 | AX16: Oxygène | AY16: 3000 | AZ16: Art.4.3 | BA16: A | BB16: Bande Butyle
B17: 6 | C17: Déverseur RBS Flottant C6 | E17: 1 | Y17: DESP 2014/68/UE Codeti 2023 Div.1 S-SG-TU-0615 | AX17: Eau glacée | AY17: 6000 | AZ17: I | BA17: A2 | BB17: Bande Grasse
B18: 7 | C18: RBS Flottant Cuve 5 | E18: 1 | Y18: DESP 2014/68/UE Codeti 2023 Div.1 S-SG-TU-0615 | AZ18: II | BA18: G | BB18: Bande Polyuréthane
B19: 8 | C19: RBS Flottant Cuve 6 | E19: 1 | Y19: DESP 2014/68/UE Codeti 2023 Div.1 S-SG-TU-0615 | AX19: Entrerré | AZ19: III
B20: 9 | C20: Déverseur soupape C6 | E20: 1 | Y20: DESP 2014/68/UE Codeti 2023 Div.1 S-SG-TU-0615 | AX20: Aérien | AY20: SMLS | BA20: SWAGELOK | BB20: SG-0131-Rev.02
B21: 10 | C21: Egouttures | E21: 1 | N21: 20CU50 | O21: 20CU50 | P21: 20CU50 | Q21: 20CU50 | Y21: DESP 2014/68/UE Codeti 2023 Div.1 S-SG-TU-0615 | AY21: ROULE SOUDE | BA21: GYROLOCK
B22: 11 | C22: Recyclage | E22: 1 | L22: THT (gaz) Azote (gaz) | M22: 50 | N22: 20SU20 | O22: 20SU20 | P22: 20SU20 | Q22: 20SU20 | R22: Aérien | S22: -20 | T22: 60 | U22: - | V22: 18 3 | W22: 4.5 | X22: Eau | Y22: DESP 2014/68/UE Codeti 2023 Div.1 S-SG-TU-0615 | AA22: I | AB22: B2 | AC22: A | AD22: OUI | AE22: 1 | AF22: 0.05 | AG22: 0.05 | AH22: 0.2 | AI22: 0.2 | AJ22: 0.05 | AL22: - | AM22: - | AN22: - | AO22: - | AP22: - | AQ22: - | AX22: OUI | AY22: OD
B23: 12 | C23: Bride recylcage | E23: 1 | Y23: DESP 2014/68/UE Codeti 2023 Div.1 S-SG-TU-0615 | AX23: NON

Sheet Données Techniques
P2: Lancement Affaire - Bureau d'Etudes
P3: DOMAINE D'APPLICATION | Q3: NATURE | R3: N° D'ORDRE | T3: VERSION
P4: ='Page de Garde'!D4 -> 2025-AF283 | Q4: LBE | R4: ='Page de Garde'!G4 -> 01 | T4: ='Page de Garde'!H4 -> v0
C6: Données Techniques : Appareils - Points de raccordements
C7: Repère | D7: Désignation | E7: Type | F7: DN | G7: PN | H7: Epaisseur | I7: Matière | J7: Fourniture | K7: Quantité | L7: Peinture | M7: Emplacement | N7: Docs Techniques / Commentaires | Q7: Affecté à la ligne… | S7: Version | T7: Reçu | U7: Traité | AC7: ARTIS
B8: =C8&" - "&D8&" - "&E8&" - "&F8&" - "&G8 -> 1 - - - - | C8: 1 | X8: FALSE | Y8: =IF(X8=TRUE,1,0) -> 0 | Z8: FALSE | AA8: =IF(Z8=TRUE,1,0) -> 0 | AB8: =IF(AA8=1,"OK","") | AC8: CLIENT
B9: =C9&" - "&D9&" - "&E9&" - "&F9&" - "&G9 -> 2 - - - - | C9: 2 | X9: FALSE | Y9: =IF(X9=TRUE,1,0) -> 0 | Z9: FALSE | AA9: =IF(Z9=TRUE,1,0) -> 0 | AB9: =IF(AA9=1,"OK","")
B10: =C10&" - "&D10&" - "&E10&" - "&F10&" - "&G10 -> 3 - - - - | C10: 3 | X10: FALSE | Y10: =IF(X10=TRUE,1,0) -> 0 | Z10: FALSE | AA10: =IF(Z10=TRUE,1,0) -> 0 | AB10: =IF(AA10=1,"OK","")
B11: =C11&" - "&D11&" - "&E11&" - "&F11&" - "&G11 -> 4 - - - - | C11: 4 | X11: FALSE | Y11: =IF(X11=TRUE,1,0) -> 0 | Z11: FALSE | AA11: =IF(Z11=TRUE,1,0) -> 0 | AB11: =IF(AA11=1,"OK","") | AC11: Sur site
B12: =C12&" - "&D12&" - "&E12&" - "&F12&" - "&G12 -> 5 - - - - | C12: 5 | X12: FALSE | Y12: =IF(X12=TRUE,1,0) -> 0 | Z12: FALSE | AA12: =IF(Z12=TRUE,1,0) -> 0 | AB12: =IF(AA12=1,"OK","") | AC12: Derval
B13: =C13&" - "&D13&" - "&E13&" - "&F13&" - "&G13 -> 6 - - - - | C13: 6 | X13: FALSE | Y13: =IF(X13=TRUE,1,0) -> 0 | Z13: FALSE | AA13: =IF(Z13=TRUE,1,0) -> 0 | AB13: =IF(AA13=1,"OK","")
B14: =C14&" - "&D14&" - "&E14&" - "&F14&" - "&G14 -> 7 - - - - | C14: 7 | X14: FALSE | Y14: =IF(X14=TRUE,1,0) -> 0 | Z14: FALSE | AA14: =IF(Z14=TRUE,1,0) -> 0 | AB14: =IF(AA14=1,"OK","")
B15: =C15&" - "&D15&" - "&E15&" - "&F15&" - "&G15 -> 8 - - - - | C15: 8 | X15: FALSE | Y15: =IF(X15=TRUE,1,0) -> 0 | Z15: FALSE | AA15: =IF(Z15=TRUE,1,0) -> 0 | AB15: =IF(AA15=1,"OK","") | AC15: OUI
B16: =C16&" - "&D16&" - "&E16&" - "&F16&" - "&G16 -> 9 - - - - | C16: 9 | X16: FALSE | Y16: =IF(X16=TRUE,1,0) -> 0 | Z16: FALSE | AA16: =IF(Z16=TRUE,1,0) -> 0 | AB16: =IF(AA16=1,"OK","") | AC16: NON
B17: =C17&" - "&D17&" - "&E17&" - "&F17&" - "&G17 -> 10 - - - - | C17: 10 | X17: FALSE | Y17: =IF(X17=TRUE,1,0) -> 0 | Z17: FALSE | AA17: =IF(Z17=TRUE,1,0) -> 0 | AB17: =IF(AA17=1,"OK","")
B18: =C18&" - "&D18&" - "&E18&" - "&F18&" - "&G18 -> 11 - - - - | C18: 11 | X18: FALSE | Y18: =IF(X18=TRUE,1,0) -> 0 | Z18: FALSE | AA18: =IF(Z18=TRUE,1,0) -> 0 | AB18: =IF(AA18=1,"OK","") | AC18: BW
B19: =C19&" - "&D19&" - "&E19&" - "&F19&" - "&G19 -> 12 - - - - | C19: 12 | X19: FALSE | Y19: =IF(X19=TRUE,1,0) -> 0 | Z19: FALSE | AA19: =IF(Z19=TRUE,1,0) -> 0 | AB19: =IF(AA19=1,"OK","") | AC19: SW
B20: =C20&" - "&D20&" - "&E20&" - "&F20&" - "&G20 -> 13 - - - - | C20: 13 | X20: FALSE | Y20: =IF(X20=TRUE,1,0) -> 0 | Z20: FALSE | AA20: =IF(Z20=TRUE,1,0) -> 0 | AB20: =IF(AA20=1,"OK","") | AC20: RJ
B21: =C21&" - "&D21&" - "&E21&" - "&F21&" - "&G21 -> 14 - - - - | C21: 14 | X21: FALSE | Y21: =IF(X21=TRUE,1,0) -> 0 | Z21: FALSE | AA21: =IF(Z21=TRUE,1,0) -> 0 | AB21: =IF(AA21=1,"OK","") | AC21: RF
B22: =C22&" - "&D22&" - "&E22&" - "&F22&" - "&G22 -> 15 - - - - | C22: 15 | X22: FALSE | Y22: =IF(X22=TRUE,1,0) -> 0 | Z22: FALSE | AA22: =IF(Z22=TRUE,1,0) -> 0 | AB22: =IF(AA22=1,"OK","") | AC22: RJ/BW
B23: =C23&" - "&D23&" - "&E23&" - "&F23&" - "&G23 -> 16 - - - - | C23: 16 | X23: FALSE | Y23: =IF(X23=TRUE,1,0) -> 0 | Z23: FALSE | AA23: =IF(Z23=TRUE,1,0) -> 0 | AB23: =IF(AA23=1,"OK","")
B24: =C24&" - "&D24&" - "&E24&" - "&F24&" - "&G24 -> 17 - - - - | C24: 17 | X24: FALSE | Y24: =IF(X24=TRUE,1,0) -> 0 | Z24: FALSE | AA24: =IF(Z24=TRUE,1,0) -> 0 | AB24: =IF(AA24=1,"OK","") | AC24: FAITE
B25: =C25&" - "&D25&" - "&E25&" - "&F25&" - "&G25 -> 18 - - - - | C25: 18 | X25: FALSE | Y25: =IF(X25=TRUE,1,0) -> 0 | Z25: FALSE | AA25: =IF(Z25=TRUE,1,0) -> 0 | AB25: =IF(AA25=1,"OK","") | AC25: A FAIRE
B26: =C26&" - "&D26&" - "&E26&" - "&F26&" - "&G26 -> 19 - - - - | C26: 19 | X26: FALSE | Y26: =IF(X26=TRUE,1,0) -> 0 | Z26: FALSE | AA26: =IF(Z26=TRUE,1,0) -> 0 | AB26: =IF(AA26=1,"OK","")
B27: =C27&" - "&D27&" - "&E27&" - "&F27&" - "&G27 -> 20 - - - - | C27: 20 | X27: FALSE | Y27: =IF(X27=TRUE,1,0) -> 0 | Z27: FALSE | AA27: =IF(Z27=TRUE,1,0) -> 0 | AB27: =IF(AA27=1,"OK","") | AC27: ACIER

Sheet Suivi des plans client
H2: Lancement Affaire - Bureau d'Etudes
H3: DOMAINE D'APPLICATION | I3: NATURE | J3: N° D'ORDRE | K3: VERSION
H4: ='Page de Garde'!$D$4 -> 2025-AF283 | I4: LBE | J4: ='Page de Garde'!$G$4 -> 01 | K4: ='Page de Garde'!$H$4 -> v0
X5: LISTE A COPIER SI NECESSAIRE
C6: RECEPTION DES PLANS CLIENT
C8: Type de plans | D8: Références du plan | E8: Révisions | F8: Reçu | G8: Traité | H8: Observations | T8: SELECTIONNER | X8: SOUDAGE
B9: =VLOOKUP(1,$W$9:$W$20,1,FALSE) -> 1 | C9: =VLOOKUP(1,W9:X20,2,FALSE) -> Plans PID | O9: FALSE | P9: =IF(O9=TRUE,1,0) -> 0 | Q9: FALSE | R9: =IF(Q9=TRUE,1,0) -> 0 | T9: x | U9: 1 | V9: =+IF(T9="","",U9) -> 1 | W9: =IF(T9="","",RANK(V9,$V$9:$V$20,1)) -> 1 | X9: Plans PID
B10: =IF(MAX($W$9:$W$20)<=1,"",VLOOKUP(B9+1,$W$9:$X$20,1,FALSE)) -> 2 | C10: =IF(MAX($W$9:$W$20)<=1,"",VLOOKUP(B9+1,$W$9:$X$20,2,FALSE)) -> Schémas / Croquis | O10: FALSE | P10: =IF(O10=TRUE,1,0) -> 0 | Q10: FALSE | R10: =IF(Q10=TRUE,1,0) -> 0 | T10: x | U10: 2 | V10: =+IF(T10="","",U10) -> 2 | W10: =IF(T10="","",RANK(V10,$V$9:$V$20,1)) -> 2 | X10: Schémas / Croquis
B11: =IF(MAX($W$9:$W$20)<=2,"",VLOOKUP(B10+1,$W$9:$X$20,1,FALSE)) -> 3 | C11: =IF(MAX($W$9:$W$20)<=2,"",VLOOKUP(B10+1,$W$9:$X$20,2,FALSE)) -> Plans Isométriques | O11: FALSE | P11: =IF(O11=TRUE,1,0) -> 0 | Q11: FALSE | R11: =IF(Q11=TRUE,1,0) -> 0 | T11: x | U11: 3 | V11: =+IF(T11="","",U11) -> 3 | W11: =IF(T11="","",RANK(V11,$V$9:$V$20,1)) -> 3 | X11: Plans Isométriques
B12: =IF(MAX($W$9:$W$20)<=3,"",VLOOKUP(B11+1,$W$9:$X$20,1,FALSE)) -> 4 | C12: =IF(MAX($W$9:$W$20)<=3,"",VLOOKUP(B11+1,$W$9:$X$20,2,FALSE)) -> Plans Tuyauterie | O12: FALSE | P12: =IF(O12=TRUE,1,0) -> 0 | Q12: FALSE | R12: =IF(Q12=TRUE,1,0) -> 0 | T12: x | U12: 4 | V12: =+IF(T12="","",U12) -> 4 | W12: =IF(T12="","",RANK(V12,$V$9:$V$20,1)) -> 4 | X12: Plans Tuyauterie
B13: =IF(MAX($W$9:$W$20)<=4,"",VLOOKUP(B12+1,$W$9:$X$20,1,FALSE)) -> 5 | C13: =IF(MAX($W$9:$W$20)<=4,"",VLOOKUP(B12+1,$W$9:$X$20,2,FALSE)) -> Plans DREAL Existant | O13: FALSE | P13: =IF(O13=TRUE,1,0) -> 0 | Q13: FALSE | R13: =IF(Q13=TRUE,1,0) -> 0 | T13: x | U13: 5 | V13: =+IF(T13="","",U13) -> 5 | W13: =IF(T13="","",RANK(V13,$V$9:$V$20,1)) -> 5 | X13: Plans DREAL Existant
B14: =IF(MAX($W$9:$W$20)<=5,"",VLOOKUP(B13+1,$W$9:$X$20,1,FALSE)) -> 6 | C14: =IF(MAX($W$9:$W$20)<=5,"",VLOOKUP(B13+1,$W$9:$X$20,2,FALSE)) -> Plans d'Implantation | O14: FALSE | P14: =IF(O14=TRUE,1,0) -> 0 | Q14: FALSE | R14: =IF(Q14=TRUE,1,0) -> 0 | T14: x | U14: 6 | V14: =+IF(T14="","",U14) -> 6 | W14: =IF(T14="","",RANK(V14,$V$9:$V$20,1)) -> 6 | X14: Plans d'Implantation
B15: =IF(MAX($W$9:$W$20)<=6,"",VLOOKUP(B14+1,$W$9:$X$20,1,FALSE)) -> 7 | C15: =IF(MAX($W$9:$W$20)<=6,"",VLOOKUP(B14+1,$W$9:$X$20,2,FALSE)) -> Maquette 3D | O15: FALSE | P15: =IF(O15=TRUE,1,0) -> 0 | Q15: FALSE | R15: =IF(Q15=TRUE,1,0) -> 0 | T15: x | U15: 7 | V15: =+IF(T15="","",U15) -> 7 | W15: =IF(T15="","",RANK(V15,$V$9:$V$20,1)) -> 7 | X15: Maquette 3D
B16: =IF(MAX($W$9:$W$20)<=7,"",VLOOKUP(B15+1,$W$9:$X$20,1,FALSE)) -> 8 | C16: =IF(MAX($W$9:$W$20)<=7,"",VLOOKUP(B15+1,$W$9:$X$20,2,FALSE)) -> Cahier des Charges | O16: FALSE | P16: =IF(O16=TRUE,1,0) -> 0 | Q16: FALSE | R16: =IF(Q16=TRUE,1,0) -> 0 | T16: x | U16: 8 | V16: =+IF(T16="","",U16) -> 8 | W16: =IF(T16="","",RANK(V16,$V$9:$V$20,1)) -> 8 | X16: Cahier des Charges
B17: =IF(MAX($W$9:$W$20)<=8,"",VLOOKUP(B16+1,$W$9:$X$20,1,FALSE)) | C17: =IF(MAX($W$9:$W$20)<=8,"",VLOOKUP(B16+1,$W$9:$X$20,2,FALSE)) | O17: FALSE | P17: =IF(O17=TRUE,1,0) -> 0 | Q17: FALSE | R17: =IF(Q17=TRUE,1,0) -> 0 | U17: 9 | V17: =+IF(T17="","",U17) | W17: =IF(T17="","",RANK(V17,$V$9:$V$20,1)) | X17: -
B18: =IF(MAX($W$9:$W$20)<=9,"",VLOOKUP(B17+1,$W$9:$X$20,1,FALSE)) | C18: =IF(MAX($W$9:$W$20)<=9,"",VLOOKUP(B17+1,$W$9:$X$20,2,FALSE)) | O18: FALSE | P18: =IF(O18=TRUE,1,0) -> 0 | Q18: FALSE | R18: =IF(Q18=TRUE,1,0) -> 0 | U18: 10 | V18: =+IF(T18="","",U18) | W18: =IF(T18="","",RANK(V18,$V$9:$V$20,1)) | X18: -
B19: =IF(MAX($W$9:$W$20)<=10,"",VLOOKUP(B18+1,$W$9:$X$20,1,FALSE)) | C19: =IF(MAX($W$9:$W$20)<=10,"",VLOOKUP(B18+1,$W$9:$X$20,2,FALSE)) | O19: FALSE | P19: =IF(O19=TRUE,1,0) -> 0 | Q19: FALSE | R19: =IF(Q19=TRUE,1,0) -> 0 | U19: 11 | V19: =+IF(T19="","",U19) | W19: =IF(T19="","",RANK(V19,$V$9:$V$20,1)) | X19: -
B20: =IF(MAX($W$9:$W$20)<=11,"",VLOOKUP(B19+1,$W$9:$X$20,1,FALSE)) | C20: =IF(MAX($W$9:$W$20)<=11,"",VLOOKUP(B19+1,$W$9:$X$20,2,FALSE)) | O20: FALSE | P20: =IF(O20=TRUE,1,0) -> 0 | Q20: FALSE | R20: =IF(Q20=TRUE,1,0) -> 0 | U20: 12 | V20: =+IF(T20="","",U20) | W20: =IF(T20="","",RANK(V20,$V$9:$V$20,1)) | X20: -

Sheet Heures BE
A1: Tâches BE | B1: Heures estimées | C1: Heures Vendues
A19: TOTAL
