Workbook

Sheet Page de Garde
D2: Lancement Affaire - Bureau d'Etudes
D3: DOMAINE D'APPLICATION | F3: NATURE | G3: N° D'ORDRE | H3: VERSION | I3: NB DE PAGES
D4: 2026-AF095 | F4: LBE | G4: 01 | H4: =IF(B21="","v0",IF(B22="","v1",IF(B23="","v2",IF(B25="","v3","")))) | I4: =+IF(D23="",IF(D22="",IF(D21="",D20,D21),D22),D23)
B6: Code client | C6: =IFERROR(VLOOKUP($D$4,'Référentiel (A COMPLETER)'!$B$5:$F$50,2,FALSE),"A COMPLETER") | F6: code resp | G6: =IFERROR(VLOOKUP($D$4,'Référentiel (A COMPLETER)'!$B$5:$F$50,4,FALSE),"A COMPLETER")
B8: N° Affaire | C8: =IF(D4="","",D4) | E8: Client | F8: NATRAN
B10: Intitulé | C10: Projet V9K23 Beynes concernant le remplacement de la vanne MSR DN400 avec raccordement
B12: Responsable Affaire ARTIS | C12: AYTE
B14: Révisions du document
B15: Version | C15: Date | D15: Modification | I15: Initiales
B16: 0 | C16: 46199 | D16: CREATION DU FICHIER
B23: Interlocuteur Client 1
B24: NOM - Prénom | D24: Poste | F24: N° Téléphone | H24: Adresse mail
B25: DUFOURNET Anne-Sophie | D25: Chef de projet | F25: 06.62.82.64.12 | H25: anne-sophie.dufournet@external.natrangroupe.com
B27: Interlocuteur Client 2 (si nécessaire)
B28: NOM - Prénom | D28: Poste | F28: N° Téléphone | H28: Adresse mail
B32: Interlocuteur ARTIS
B33: Nom - Prénom | C33: Fonction | D33: Adresse | F33: Téléphone fixe | G33: Téléphone mobile | H33: E-mail

Sheet Actions - Liste des livrables
D2: Lancement Affaire - Bureau d'Etudes
D3: DOMAINE D'APPLICATION | E3: NATURE | F3: N° D'ORDRE | G3: VERSION
D4: ='Page de Garde'!D4 | E4: LBE | F4: ='Page de Garde'!G4 | G4: ='Page de Garde'!H4
C6: ACTIONS BUREAU D'ETUDES
C7: LIVRABLES CLIENT
C8: DOCUMENTS A PRODUIRE | M8: LISTE A COPIER SI NECESSAIRE
C10: Elément | E10: COMMENTAIRES | I10: SELECTIONNER | M10: Elément
B11: =VLOOKUP(1,$L$11:$L$31,1,FALSE) | C11: =VLOOKUP(1,L11:M46,2,FALSE) | I11: x | J11: 1 | K11: =+IF(I11="","",J11) | L11: =IF(I11="","",RANK(K11,$K$11:$K$46,1)) | M11: Nomenclature
B12: =IF(MAX($L$11:$L$46)<=1,"",VLOOKUP(B11+1,$L$11:$M$46,1,FALSE)) | C12: =IF(MAX($L$11:$L$46)<=1,"",VLOOKUP(B11+1,$L$11:$M$46,2,FALSE)) | J12: 2 | K12: =+IF(I12="","",J12) | L12: =IF(I12="","",RANK(K12,$K$11:$K$46,1)) | M12: Plans isométriques manuel
B13: =IF(MAX($L$11:$L$46)<=2,"",VLOOKUP(B12+1,$L$11:$M$46,1,FALSE)) | C13: =IF(MAX($L$11:$L$46)<=2,"",VLOOKUP(B12+1,$L$11:$M$46,2,FALSE)) | J13: 3 | K13: =+IF(I13="","",J13) | L13: =IF(I13="","",RANK(K13,$K$11:$K$46,1)) | M13: Résa 80%
B14: =IF(MAX($L$11:$L$46)<=3,"",VLOOKUP(B13+1,$L$11:$M$46,1,FALSE)) | C14: =IF(MAX($L$11:$L$46)<=3,"",VLOOKUP(B13+1,$L$11:$M$46,2,FALSE)) | J14: 4 | K14: =+IF(I14="","",J14) | L14: =IF(I14="","",RANK(K14,$K$11:$K$46,1)) | M14: Plans 3D
B15: =IF(MAX($L$11:$L$46)<=4,"",VLOOKUP(B14+1,$L$11:$M$46,1,FALSE)) | C15: =IF(MAX($L$11:$L$46)<=4,"",VLOOKUP(B14+1,$L$11:$M$46,2,FALSE)) | I15: x | J15: 5 | K15: =+IF(I15="","",J15) | L15: =IF(I15="","",RANK(K15,$K$11:$K$46,1)) | M15: Plans TUT
B16: =IF(MAX($L$11:$L$46)<=5,"",VLOOKUP(B15+1,$L$11:$M$46,1,FALSE)) | C16: =IF(MAX($L$11:$L$46)<=5,"",VLOOKUP(B15+1,$L$11:$M$46,2,FALSE)) | E16: A valider avec le sous-traitant | J16: 6 | K16: =+IF(I16="","",J16) | L16: =IF(I16="","",RANK(K16,$K$11:$K$46,1)) | M16: Résa 100%
B17: =IF(MAX($L$11:$L$46)<=6,"",VLOOKUP(B16+1,$L$11:$M$46,1,FALSE)) | C17: =IF(MAX($L$11:$L$46)<=6,"",VLOOKUP(B16+1,$L$11:$M$46,2,FALSE)) | I17: x | J17: 7 | K17: =+IF(I17="","",J17) | L17: =IF(I17="","",RANK(K17,$K$11:$K$46,1)) | M17: Plans isométriques - Repérage pièces
B18: =IF(MAX($L$11:$L$46)<=7,"",VLOOKUP(B17+1,$L$11:$M$46,1,FALSE)) | C18: =IF(MAX($L$11:$L$46)<=7,"",VLOOKUP(B17+1,$L$11:$M$46,2,FALSE)) | I18: x | J18: 8 | K18: =+IF(I18="","",J18) | L18: =IF(I18="","",RANK(K18,$K$11:$K$46,1)) | M18: Plans isométriques - Repérage soudures
B19: =IF(MAX($L$11:$L$46)<=8,"",VLOOKUP(B18+1,$L$11:$M$46,1,FALSE)) | C19: =IF(MAX($L$11:$L$46)<=8,"",VLOOKUP(B18+1,$L$11:$M$46,2,FALSE)) | I19: x | J19: 9 | K19: =+IF(I19="","",J19) | L19: =IF(I19="","",RANK(K19,$K$11:$K$46,1)) | M19: Tableau de débits
B20: =IF(MAX($L$11:$L$46)<=9,"",VLOOKUP(B19+1,$L$11:$M$46,1,FALSE)) | C20: =IF(MAX($L$11:$L$46)<=9,"",VLOOKUP(B19+1,$L$11:$M$46,2,FALSE)) | E20: A valider | I20: x | J20: 10 | K20: =+IF(I20="","",J20) | L20: =IF(I20="","",RANK(K20,$K$11:$K$46,1)) | M20: Plans GC
B21: =IF(MAX($L$11:$L$46)<=10,"",VLOOKUP(B20+1,$L$11:$M$46,1,FALSE)) | C21: =IF(MAX($L$11:$L$46)<=10,"",VLOOKUP(B20+1,$L$11:$M$46,2,FALSE)) | E21: Réaliser par Adekma | I21: x | J21: 11 | K21: =+IF(I21="","",J21) | L21: =IF(I21="","",RANK(K21,$K$11:$K$46,1)) | M21: Plans de manchettes délardées
B22: =IF(MAX($L$11:$L$46)<=11,"",VLOOKUP(B21+1,$L$11:$M$46,1,FALSE)) | C22: =IF(MAX($L$11:$L$46)<=11,"",VLOOKUP(B21+1,$L$11:$M$46,2,FALSE)) | E22: A préciser sur le plan TUT | J22: 12 | K22: =+IF(I22="","",J22) | L22: =IF(I22="","",RANK(K22,$K$11:$K$46,1)) | M22: Plans de châssis
B23: =IF(MAX($L$11:$L$46)<=12,"",VLOOKUP(B22+1,$L$11:$M$46,1,FALSE)) | C23: =IF(MAX($L$11:$L$46)<=12,"",VLOOKUP(B22+1,$L$11:$M$46,2,FALSE)) | E23: A valider auprès du client | J23: 13 | K23: =+IF(I23="","",J23) | L23: =IF(I23="","",RANK(K23,$K$11:$K$46,1)) | M23: Plans de terrassement
B24: =IF(MAX($L$11:$L$46)<=13,"",VLOOKUP(B23+1,$L$11:$M$46,1,FALSE)) | C24: =IF(MAX($L$11:$L$46)<=13,"",VLOOKUP(B23+1,$L$11:$M$46,2,FALSE)) | E24: A valider auprès du client | J24: 14 | K24: =+IF(I24="","",J24) | L24: =IF(I24="","",RANK(K24,$K$11:$K$46,1)) | M24: Plans d'installation chantier / Base vie
B25: =IF(MAX($L$11:$L$46)<=14,"",VLOOKUP(B24+1,$L$11:$M$46,1,FALSE)) | C25: =IF(MAX($L$11:$L$46)<=14,"",VLOOKUP(B24+1,$L$11:$M$46,2,FALSE)) | E25: A valider auprès du client | I25: x | J25: 15 | K25: =+IF(I25="","",J25) | L25: =IF(I25="","",RANK(K25,$K$11:$K$46,1)) | M25: Plans de montage d'épreuve/séchage
B26: =IF(MAX($L$11:$L$46)<=15,"",VLOOKUP(B25+1,$L$11:$M$46,1,FALSE)) | C26: =IF(MAX($L$11:$L$46)<=15,"",VLOOKUP(B25+1,$L$11:$M$46,2,FALSE)) | I26: x | J26: 16 | K26: =+IF(I26="","",J26) | L26: =IF(I26="","",RANK(K26,$K$11:$K$46,1)) | M26: Plans isométriques - Repérage brides et appareils
B27: =IF(MAX($L$11:$L$46)<=16,"",VLOOKUP(B26+1,$L$11:$M$46,1,FALSE)) | C27: =IF(MAX($L$11:$L$46)<=16,"",VLOOKUP(B26+1,$L$11:$M$46,2,FALSE)) | I27: x | J27: 17 | K27: =+IF(I27="","",J27) | L27: =IF(I27="","",RANK(K27,$K$11:$K$46,1)) | M27: Plans de sertissage
B28: =IF(MAX($L$11:$L$46)<=17,"",VLOOKUP(B27+1,$L$11:$M$46,1,FALSE)) | C28: =IF(MAX($L$11:$L$46)<=17,"",VLOOKUP(B27+1,$L$11:$M$46,2,FALSE)) | E28: Pour le tubing ? | I28: x | J28: 18 | K28: =+IF(I28="","",J28) | L28: =IF(I28="","",RANK(K28,$K$11:$K$46,1)) | M28: Plans Levage
B29: =IF(MAX($L$11:$L$46)<=18,"",VLOOKUP(B28+1,$L$11:$M$46,1,FALSE)) | C29: =IF(MAX($L$11:$L$46)<=18,"",VLOOKUP(B28+1,$L$11:$M$46,2,FALSE)) | J29: 19 | K29: =+IF(I29="","",J29) | L29: =IF(I29="","",RANK(K29,$K$11:$K$46,1)) | M29: Montage sur site
B30: =IF(MAX($L$11:$L$46)<=19,"",VLOOKUP(B29+1,$L$11:$M$46,1,FALSE)) | C30: =IF(MAX($L$11:$L$46)<=19,"",VLOOKUP(B29+1,$L$11:$M$46,2,FALSE)) | I30: x | J30: 20 | K30: =+IF(I30="","",J30) | L30: =IF(I30="","",RANK(K30,$K$11:$K$46,1)) | M30: Plans enrobage / Peinture
B31: =IF(MAX($L$11:$L$46)<=20,"",VLOOKUP(B30+1,$L$11:$M$46,1,FALSE)) | C31: =IF(MAX($L$11:$L$46)<=20,"",VLOOKUP(B30+1,$L$11:$M$46,2,FALSE)) | J31: 21 | K31: =+IF(I31="","",J31) | L31: =IF(I31="","",RANK(K31,$K$11:$K$46,1)) | M31: Maquette 3D
B32: =IF(MAX($L$11:$L$46)<=21,"",VLOOKUP(B31+1,$L$11:$M$46,1,FALSE)) | C32: =IF(MAX($L$11:$L$46)<=21,"",VLOOKUP(B31+1,$L$11:$M$46,2,FALSE)) | I32: x | J32: 22 | K32: =+IF(I32="","",J32) | L32: =IF(I32="","",RANK(K32,$K$11:$K$46,1)) | M32: GDER TUT
B33: =IF(MAX($L$11:$L$46)<=22,"",VLOOKUP(B32+1,$L$11:$M$46,1,FALSE)) | C33: =IF(MAX($L$11:$L$46)<=22,"",VLOOKUP(B32+1,$L$11:$M$46,2,FALSE)) | I33: x | J33: 23 | K33: =+IF(I33="","",J33) | L33: =IF(I33="","",RANK(K33,$K$11:$K$46,1)) | M33: GDER GCT
B34: =IF(MAX($L$11:$L$46)<=23,"",VLOOKUP(B33+1,$L$11:$M$46,1,FALSE)) | C34: =IF(MAX($L$11:$L$46)<=23,"",VLOOKUP(B33+1,$L$11:$M$46,2,FALSE)) | I34: x | J34: 24 | K34: =+IF(I34="","",J34) | L34: =IF(I34="","",RANK(K34,$K$11:$K$46,1)) | M34: GDER DREAL
B35: =IF(MAX($L$11:$L$46)<=24,"",VLOOKUP(B34+1,$L$11:$M$46,1,FALSE)) | C35: =IF(MAX($L$11:$L$46)<=24,"",VLOOKUP(B34+1,$L$11:$M$46,2,FALSE)) | J35: 25 | K35: =+IF(I35="","",J35) | L35: =IF(I35="","",RANK(K35,$K$11:$K$46,1)) | M35: Spécifique (à préciser)
B36: =IF(MAX($L$11:$L$46)<=25,"",VLOOKUP(B35+1,$L$11:$M$46,1,FALSE)) | C36: =IF(MAX($L$11:$L$46)<=25,"",VLOOKUP(B35+1,$L$11:$M$46,2,FALSE)) | J36: 26 | K36: =+IF(I36="","",J36) | L36: =IF(I36="","",RANK(K36,$K$11:$K$46,1))
B37: =IF(MAX($L$11:$L$46)<=26,"",VLOOKUP(B36+1,$L$11:$M$46,1,FALSE)) | C37: =IF(MAX($L$11:$L$46)<=26,"",VLOOKUP(B36+1,$L$11:$M$46,2,FALSE)) | I37: x | J37: 27 | K37: =+IF(I37="","",J37) | L37: =IF(I37="","",RANK(K37,$K$11:$K$46,1)) | M37: Cahier de soudage avec validation pré-soudage
B38: =IF(MAX($L$11:$L$46)<=27,"",VLOOKUP(B37+1,$L$11:$M$46,1,FALSE)) | C38: =IF(MAX($L$11:$L$46)<=27,"",VLOOKUP(B37+1,$L$11:$M$46,2,FALSE)) | J38: 28 | K38: =+IF(I38="","",J38) | L38: =IF(I38="","",RANK(K38,$K$11:$K$46,1)) | M38: DMOS / QMOS /QS
B39: =IF(MAX($L$11:$L$46)<=28,"",VLOOKUP(B38+1,$L$11:$M$46,1,FALSE)) | C39: =IF(MAX($L$11:$L$46)<=28,"",VLOOKUP(B38+1,$L$11:$M$46,2,FALSE)) | J39: 29 | K39: =+IF(I39="","",J39) | L39: =IF(I39="","",RANK(K39,$K$11:$K$46,1)) | M39: Dossier d'épreuve selon DESP 2014/68/UE
B40: =IF(MAX($L$11:$L$46)<=29,"",VLOOKUP(B39+1,$L$11:$M$46,1,FALSE)) | C40: =IF(MAX($L$11:$L$46)<=29,"",VLOOKUP(B39+1,$L$11:$M$46,2,FALSE)) | I40: x | J40: 30 | K40: =+IF(I40="","",J40) | L40: =IF(I40="","",RANK(K40,$K$11:$K$46,1)) | M40: Dossier d'épreuve selon A.M du 05/03/2014
B41: =IF(MAX($L$11:$L$46)<=30,"",VLOOKUP(B40+1,$L$11:$M$46,1,FALSE)) | C41: =IF(MAX($L$11:$L$46)<=30,"",VLOOKUP(B40+1,$L$11:$M$46,2,FALSE)) | I41: x | J41: 31 | K41: =+IF(I41="","",J41) | L41: =IF(I41="","",RANK(K41,$K$11:$K$46,1)) | M41: Dossier de Fabrication selon Art.4.3
B42: =IF(MAX($L$11:$L$46)<=31,"",VLOOKUP(B41+1,$L$11:$M$46,1,FALSE)) | C42: =IF(MAX($L$11:$L$46)<=31,"",VLOOKUP(B41+1,$L$11:$M$46,2,FALSE)) | I42: x | J42: 32 | K42: =+IF(I42="","",J42) | L42: =IF(I42="","",RANK(K42,$K$11:$K$46,1)) | M42: Relevé Epaisseur Manchette délardée
B43: =IF(MAX($L$11:$L$46)<=32,"",VLOOKUP(B42+1,$L$11:$M$46,1,FALSE)) | C43: =IF(MAX($L$11:$L$46)<=32,"",VLOOKUP(B42+1,$L$11:$M$46,2,FALSE)) | J43: 33 | K43: =+IF(I43="","",J43) | L43: =IF(I43="","",RANK(K43,$K$11:$K$46,1)) | M43: PV Cintrage
...

Sheet Liste des lignes
F2: Lancement Affaire - Bureau d'Etudes
F3: DOMAINE D'APPLICATION | G3: NATURE | H3: N° D'ORDRE | I3: VERSION
F4: ='Page de Garde'!$D$4 | G4: LBE | H4: ='Page de Garde'!$G$4 | I4: ='Page de Garde'!$H$4
B6: LISTE DES LIGNES
B9: Information : 1 TYPE DE LIGNE = 1 Dossier EH | K9: CARACTERISTIQUES DES LIGNES
B10: N° | C10: NOM DE LA LIGNE | E10: QUANTITE | F10: SENS DU FLUIDE | K10: CONDITIONS OPERATOIRES | U10: INSPECTION /CONDITIONS EH | AC10: CONTROLES | AK10: Autres
F11: VENANT DE | H11: ALLANT VERS | K11: FLUIDE | L11: DN MAX | M11: MATIERE | N11: TYPE DE TUBE | O11: EP ou SCH | P11: SERIE RACCORD | Q11: ENTERRE ou AERIEN | R11: T°C Min | S11: T°C Max | T11: LONGUEUR | U11: PS ou PMC | V11: PT | W11: FLUIDE EH | X11: REGLEMENTATION | Y11: CAT. EMP. (Transport) | Z11: CAT. RISQUE (DESP) | AA11: CAT. CONSTRUCTION (DESP) | AB11: MODULE EVALUATION (DESP) | AC11: PLAQUE CE | AD11: %VT (BW-SW-FW) | AE11: %RT (BW) | AF11: %RT (SW) | AG11: %PT (BW) | AH11: %PT (SW) | AI11: %PT (FW) | AJ11: %UT (Avant Perçage) | AK11: RAL PEINTURE | AL11: SPECIFICATION PEINTURE | AM11: TYPE ENROBAGE | AN11: SPECIFICATION ENROBAGE | AO11: PRESCRIPTION TUBING | AP11: TYPE DE SUPPORTAGE | AQ11: COMMENTAIRES | AW11: Gaz Naturel | AX11: Codeti 2013 Rev.11/16 | AY11: C | AZ11: C | BA11: TRAPIL
B12: =1 | C12: Remplacement Vanne 10-MV-1100 | E12: 1 | F12: Ligne DN400 | H12: Ligne DN400 | K12: Gaz Naturel | L12: 400 | M12: 100CP1 | N12: 100CP1 | O12: 100CP1 | P12: 100CP1 | Q12: Aérien | R12: -29 | S12: 60 | T12: - | U12: 40 67.7 | V12: =1.3*67.7 | W12: Eau | X12: A.M. du 05/03/2014 SG-M-322 Rev.5 SG-0015 | Y12: B | AD12: 1 | AE12: 1 | AF12: 1 | AH12: 1 | AI12: 1 | AJ12: 1 | AK12: 6005 | AL12: ACQPA C4 SG-0129 | AM12: Trenton Denso | AN12: SG-0131-Rev.07 | AP12: SU-017-S | AQ12: Manchette délardée | AW12: Eau Chaude | AX12: A.M. du 05/03/2014 | AY12: B | AZ12: B2 | BA12: Air Liquide
B13: 2 | C13: Remplacement Vanne 10-HV-T111 | E13: 1 | F13: Bride DN150 PN100 RJ | H13: Bride DN150 PN68 RJ | K13: Gaz Naturel | L13: 150 | M13: 100CP1 | N13: 100CP1 | O13: 100CP1 | P13: 100CP1 | Q13: Aérien | R13: -29 | S13: 60 | T13: - | U13: 40 67.7 | V13: =1.3*67.7 | W13: Eau | X13: A.M. du 05/03/2014 SG-M-322 Rev.5 SG-0015 | Y13: B | AD13: 1 | AE13: 1 | AF13: 1 | AH13: 1 | AI13: 1 | AJ13: 1 | AK13: 6005 | AW13: AFGAS | AX13: CODAP 2015 | AY13: A | AZ13: B1 | BA13: ACQPA C3
B14: 3 | C14: Remplacement équilibrage gare | E14: 1 | F14: 10-PL-6 | H14: 10-HV-671 10-HV-673 10-HV-674 | K14: Gaz Naturel | L14: 50 | M14: 100CP1 | N14: 100CP1 | O14: 100CP1 | P14: 100CP1 | Q14: Aérien | R14: -29 | S14: 60 | T14: - | U14: 40 67.7 | V14: =1.3*67.7 | W14: Eau | X14: A.M. du 05/03/2014 SG-M-322 Rev.5 SG-0015 | Y14: B | AD14: 1 | AE14: 1 | AF14: 1 | AH14: 1 | AI14: 1 | AJ14: 1 | AK14: 6005 | AW14: JET-A1 | AZ14: A | BA14: ACQPA C4
AW15: Azote
B16: 5 | AW16: Oxygène | AX16: 3000 | AY16: Art.4.3 | AZ16: A | BA16: Bande Butyle
B17: 6 | AW17: Eau glacée | AX17: 6000 | AY17: I | AZ17: A2 | BA17: Bande Grasse
B18: 7 | AY18: II | AZ18: G | BA18: Bande Polyuréthane
B19: 8 | AW19: Entrerré | AY19: III
B20: 9 | AW20: Aérien | AX20: SMLS | AZ20: SWAGELOK | BA20: SG-0131-Rev.02
B21: 10 | AX21: ROULE SOUDE | AZ21: GYROLOCK
B22: 11 | AW22: OUI | AX22: OD
B23: 12 | AW23: NON
B26: VALIDATION CONDUCTEUR DE TRAVAUX | F26: VALIDATION DIRECTEUR TECHNIQUE
B29: Date | F29: Date
B31: Version | F31: Version
B33: Visa | F33: Visa
C40: FCH Fabrice CHAILLOUX
C45: LLE Laurent LEMOINE
C50: ATO Axel TOMEKPE
C55: GJO Guillaume JOUADE
C60: DBE David BENARD
C65: MVI Maxime VINCENDEAU

Sheet Données Techniques
P2: Lancement Affaire - Bureau d'Etudes
P3: DOMAINE D'APPLICATION | Q3: NATURE | R3: N° D'ORDRE | T3: VERSION
P4: ='Page de Garde'!D4 | Q4: LBE | R4: ='Page de Garde'!G4 | T4: ='Page de Garde'!H4
C6: Données Techniques : Appareils - Points de raccordements
C7: Repère | D7: Désignation | E7: Type | F7: DN | G7: PN | H7: Epaisseur | I7: Matière | J7: Fourniture | K7: Quantité | L7: Peinture | M7: Emplacement | N7: Docs Techniques / Commentaires | Q7: Affecté à la ligne… | S7: Version | T7: Reçu | U7: Traité | AC7: ARTIS
B8: =C8&" - "&D8&" - "&E8&" - "&F8&" - "&G8 | C8: 1 | D8: Raccordement DN400 amont | E8: BW | F8: 400 | I8: ACIER | J8: CLIENT | K8: 1 | L8: RAL 6005 | M8: Derval | Q8: 1 | X8: FALSE | Y8: =IF(X8=TRUE,1,0) | Z8: FALSE | AA8: =IF(Z8=TRUE,1,0) | AB8: =IF(AA8=1,"OK","") | AC8: CLIENT
B9: =C9&" - "&D9&" - "&E9&" - "&F9&" - "&G9 | C9: 2 | D9: Raccordement DN400 aval | E9: BW | F9: 400 | I9: ACIER | J9: CLIENT | K9: 1 | L9: RAL 6005 | M9: Derval | Q9: 1 | X9: FALSE | Y9: =IF(X9=TRUE,1,0) | Z9: FALSE | AA9: =IF(Z9=TRUE,1,0) | AB9: =IF(AA9=1,"OK","")
B10: =C10&" - "&D10&" - "&E10&" - "&F10&" - "&G10 | C10: 3 | D10: Raccordement bride DN150 PN100 RJ | E10: BW | F10: 150 | G10: 100 | I10: ACIER | J10: CLIENT | K10: 1 | L10: RAL 6005 | M10: Derval | Q10: 2 | X10: FALSE | Y10: =IF(X10=TRUE,1,0) | Z10: FALSE | AA10: =IF(Z10=TRUE,1,0) | AB10: =IF(AA10=1,"OK","")
B11: =C11&" - "&D11&" - "&E11&" - "&F11&" - "&G11 | C11: 4 | D11: Raccordement bride DN150 PN68 RJ | E11: BW | F11: 150 | G11: 68 | I11: ACIER | J11: CLIENT | K11: 1 | L11: RAL 6005 | M11: Derval | Q11: 2 | X11: FALSE | Y11: =IF(X11=TRUE,1,0) | Z11: FALSE | AA11: =IF(Z11=TRUE,1,0) | AB11: =IF(AA11=1,"OK","") | AC11: Sur site
B12: =C12&" - "&D12&" - "&E12&" - "&F12&" - "&G12 | C12: 5 | D12: Raccordement bride 10-PL-6 | E12: BW | F12: 50 | I12: ACIER | J12: CLIENT | K12: 1 | L12: RAL 6005 | M12: Derval | Q12: 3 | X12: FALSE | Y12: =IF(X12=TRUE,1,0) | Z12: FALSE | AA12: =IF(Z12=TRUE,1,0) | AB12: =IF(AA12=1,"OK","") | AC12: Derval
B13: =C13&" - "&D13&" - "&E13&" - "&F13&" - "&G13 | C13: 6 | D13: Raccordement bride 10-HV-671 10-HV-673 10-HV-674 | E13: BW | F13: 50 | I13: ACIER | J13: CLIENT | K13: 1 | L13: RAL 6005 | M13: Derval | Q13: 3 | X13: FALSE | Y13: =IF(X13=TRUE,1,0) | Z13: FALSE | AA13: =IF(Z13=TRUE,1,0) | AB13: =IF(AA13=1,"OK","")
B14: =C14&" - "&D14&" - "&E14&" - "&F14&" - "&G14 | C14: 7 | X14: FALSE | Y14: =IF(X14=TRUE,1,0) | Z14: FALSE | AA14: =IF(Z14=TRUE,1,0) | AB14: =IF(AA14=1,"OK","")
B15: =C15&" - "&D15&" - "&E15&" - "&F15&" - "&G15 | C15: 8 | X15: FALSE | Y15: =IF(X15=TRUE,1,0) | Z15: FALSE | AA15: =IF(Z15=TRUE,1,0) | AB15: =IF(AA15=1,"OK","") | AC15: OUI
B16: =C16&" - "&D16&" - "&E16&" - "&F16&" - "&G16 | C16: 9 | X16: FALSE | Y16: =IF(X16=TRUE,1,0) | Z16: FALSE | AA16: =IF(Z16=TRUE,1,0) | AB16: =IF(AA16=1,"OK","") | AC16: NON
B17: =C17&" - "&D17&" - "&E17&" - "&F17&" - "&G17 | C17: 10 | X17: FALSE | Y17: =IF(X17=TRUE,1,0) | Z17: FALSE | AA17: =IF(Z17=TRUE,1,0) | AB17: =IF(AA17=1,"OK","")
B18: =C18&" - "&D18&" - "&E18&" - "&F18&" - "&G18 | C18: 11 | X18: FALSE | Y18: =IF(X18=TRUE,1,0) | Z18: FALSE | AA18: =IF(Z18=TRUE,1,0) | AB18: =IF(AA18=1,"OK","") | AC18: BW
B19: =C19&" - "&D19&" - "&E19&" - "&F19&" - "&G19 | C19: 12 | X19: FALSE | Y19: =IF(X19=TRUE,1,0) | Z19: FALSE | AA19: =IF(Z19=TRUE,1,0) | AB19: =IF(AA19=1,"OK","") | AC19: SW
B20: =C20&" - "&D20&" - "&E20&" - "&F20&" - "&G20 | C20: 13 | X20: FALSE | Y20: =IF(X20=TRUE,1,0) | Z20: FALSE | AA20: =IF(Z20=TRUE,1,0) | AB20: =IF(AA20=1,"OK","") | AC20: RJ
B21: =C21&" - "&D21&" - "&E21&" - "&F21&" - "&G21 | C21: 14 | X21: FALSE | Y21: =IF(X21=TRUE,1,0) | Z21: FALSE | AA21: =IF(Z21=TRUE,1,0) | AB21: =IF(AA21=1,"OK","") | AC21: RF
B22: =C22&" - "&D22&" - "&E22&" - "&F22&" - "&G22 | C22: 15 | X22: FALSE | Y22: =IF(X22=TRUE,1,0) | Z22: FALSE | AA22: =IF(Z22=TRUE,1,0) | AB22: =IF(AA22=1,"OK","") | AC22: RJ/BW
B23: =C23&" - "&D23&" - "&E23&" - "&F23&" - "&G23 | C23: 16 | X23: FALSE | Y23: =IF(X23=TRUE,1,0) | Z23: FALSE | AA23: =IF(Z23=TRUE,1,0) | AB23: =IF(AA23=1,"OK","")
B24: =C24&" - "&D24&" - "&E24&" - "&F24&" - "&G24 | C24: 17 | X24: FALSE | Y24: =IF(X24=TRUE,1,0) | Z24: FALSE | AA24: =IF(Z24=TRUE,1,0) | AB24: =IF(AA24=1,"OK","") | AC24: FAITE
B25: =C25&" - "&D25&" - "&E25&" - "&F25&" - "&G25 | C25: 18 | X25: FALSE | Y25: =IF(X25=TRUE,1,0) | Z25: FALSE | AA25: =IF(Z25=TRUE,1,0) | AB25: =IF(AA25=1,"OK","") | AC25: A FAIRE
B26: =C26&" - "&D26&" - "&E26&" - "&F26&" - "&G26 | C26: 19 | X26: FALSE | Y26: =IF(X26=TRUE,1,0) | Z26: FALSE | AA26: =IF(Z26=TRUE,1,0) | AB26: =IF(AA26=1,"OK","")
B27: =C27&" - "&D27&" - "&E27&" - "&F27&" - "&G27 | C27: 20 | X27: FALSE | Y27: =IF(X27=TRUE,1,0) | Z27: FALSE | AA27: =IF(Z27=TRUE,1,0) | AB27: =IF(AA27=1,"OK","") | AC27: ACIER

Sheet Suivi des plans client
H2: Lancement Affaire - Bureau d'Etudes
H3: DOMAINE D'APPLICATION | I3: NATURE | J3: N° D'ORDRE | K3: VERSION
H4: ='Page de Garde'!$D$4 | I4: LBE | J4: ='Page de Garde'!$G$4 | K4: ='Page de Garde'!$H$4
X5: LISTE A COPIER SI NECESSAIRE
C6: RECEPTION DES PLANS CLIENT
C8: Type de plans | D8: Références du plan | E8: Révisions | F8: Reçu | G8: Traité | H8: Observations | T8: SELECTIONNER | X8: SOUDAGE
B9: =VLOOKUP(1,$W$9:$W$20,1,FALSE) | C9: =VLOOKUP(1,W9:X20,2,FALSE) | O9: FALSE | P9: =IF(O9=TRUE,1,0) | Q9: FALSE | R9: =IF(Q9=TRUE,1,0) | T9: x | U9: 1 | V9: =+IF(T9="","",U9) | W9: =IF(T9="","",RANK(V9,$V$9:$V$20,1)) | X9: Plans PID
B10: =IF(MAX($W$9:$W$20)<=1,"",VLOOKUP(B9+1,$W$9:$X$20,1,FALSE)) | C10: =IF(MAX($W$9:$W$20)<=1,"",VLOOKUP(B9+1,$W$9:$X$20,2,FALSE)) | O10: FALSE | P10: =IF(O10=TRUE,1,0) | Q10: FALSE | R10: =IF(Q10=TRUE,1,0) | T10: x | U10: 2 | V10: =+IF(T10="","",U10) | W10: =IF(T10="","",RANK(V10,$V$9:$V$20,1)) | X10: Schémas / Croquis
B11: =IF(MAX($W$9:$W$20)<=2,"",VLOOKUP(B10+1,$W$9:$X$20,1,FALSE)) | C11: =IF(MAX($W$9:$W$20)<=2,"",VLOOKUP(B10+1,$W$9:$X$20,2,FALSE)) | O11: FALSE | P11: =IF(O11=TRUE,1,0) | Q11: FALSE | R11: =IF(Q11=TRUE,1,0) | T11: x | U11: 3 | V11: =+IF(T11="","",U11) | W11: =IF(T11="","",RANK(V11,$V$9:$V$20,1)) | X11: Plans Isométriques
B12: =IF(MAX($W$9:$W$20)<=3,"",VLOOKUP(B11+1,$W$9:$X$20,1,FALSE)) | C12: =IF(MAX($W$9:$W$20)<=3,"",VLOOKUP(B11+1,$W$9:$X$20,2,FALSE)) | O12: FALSE | P12: =IF(O12=TRUE,1,0) | Q12: FALSE | R12: =IF(Q12=TRUE,1,0) | T12: x | U12: 4 | V12: =+IF(T12="","",U12) | W12: =IF(T12="","",RANK(V12,$V$9:$V$20,1)) | X12: Plans Tuyauterie
B13: =IF(MAX($W$9:$W$20)<=4,"",VLOOKUP(B12+1,$W$9:$X$20,1,FALSE)) | C13: =IF(MAX($W$9:$W$20)<=4,"",VLOOKUP(B12+1,$W$9:$X$20,2,FALSE)) | O13: FALSE | P13: =IF(O13=TRUE,1,0) | Q13: FALSE | R13: =IF(Q13=TRUE,1,0) | T13: x | U13: 5 | V13: =+IF(T13="","",U13) | W13: =IF(T13="","",RANK(V13,$V$9:$V$20,1)) | X13: Plans DREAL Existant
B14: =IF(MAX($W$9:$W$20)<=5,"",VLOOKUP(B13+1,$W$9:$X$20,1,FALSE)) | C14: =IF(MAX($W$9:$W$20)<=5,"",VLOOKUP(B13+1,$W$9:$X$20,2,FALSE)) | O14: FALSE | P14: =IF(O14=TRUE,1,0) | Q14: FALSE | R14: =IF(Q14=TRUE,1,0) | T14: x | U14: 6 | V14: =+IF(T14="","",U14) | W14: =IF(T14="","",RANK(V14,$V$9:$V$20,1)) | X14: Plans d'Implantation
B15: =IF(MAX($W$9:$W$20)<=6,"",VLOOKUP(B14+1,$W$9:$X$20,1,FALSE)) | C15: =IF(MAX($W$9:$W$20)<=6,"",VLOOKUP(B14+1,$W$9:$X$20,2,FALSE)) | O15: FALSE | P15: =IF(O15=TRUE,1,0) | Q15: FALSE | R15: =IF(Q15=TRUE,1,0) | T15: x | U15: 7 | V15: =+IF(T15="","",U15) | W15: =IF(T15="","",RANK(V15,$V$9:$V$20,1)) | X15: Maquette 3D
B16: =IF(MAX($W$9:$W$20)<=7,"",VLOOKUP(B15+1,$W$9:$X$20,1,FALSE)) | C16: =IF(MAX($W$9:$W$20)<=7,"",VLOOKUP(B15+1,$W$9:$X$20,2,FALSE)) | O16: FALSE | P16: =IF(O16=TRUE,1,0) | Q16: FALSE | R16: =IF(Q16=TRUE,1,0) | T16: x | U16: 8 | V16: =+IF(T16="","",U16) | W16: =IF(T16="","",RANK(V16,$V$9:$V$20,1)) | X16: Cahier des Charges
B17: =IF(MAX($W$9:$W$20)<=8,"",VLOOKUP(B16+1,$W$9:$X$20,1,FALSE)) | C17: =IF(MAX($W$9:$W$20)<=8,"",VLOOKUP(B16+1,$W$9:$X$20,2,FALSE)) | O17: FALSE | P17: =IF(O17=TRUE,1,0) | Q17: FALSE | R17: =IF(Q17=TRUE,1,0) | U17: 9 | V17: =+IF(T17="","",U17) | W17: =IF(T17="","",RANK(V17,$V$9:$V$20,1)) | X17: -
B18: =IF(MAX($W$9:$W$20)<=9,"",VLOOKUP(B17+1,$W$9:$X$20,1,FALSE)) | C18: =IF(MAX($W$9:$W$20)<=9,"",VLOOKUP(B17+1,$W$9:$X$20,2,FALSE)) | O18: FALSE | P18: =IF(O18=TRUE,1,0) | Q18: FALSE | R18: =IF(Q18=TRUE,1,0) | U18: 10 | V18: =+IF(T18="","",U18) | W18: =IF(T18="","",RANK(V18,$V$9:$V$20,1)) | X18: -
B19: =IF(MAX($W$9:$W$20)<=10,"",VLOOKUP(B18+1,$W$9:$X$20,1,FALSE)) | C19: =IF(MAX($W$9:$W$20)<=10,"",VLOOKUP(B18+1,$W$9:$X$20,2,FALSE)) | O19: FALSE | P19: =IF(O19=TRUE,1,0) | Q19: FALSE | R19: =IF(Q19=TRUE,1,0) | U19: 11 | V19: =+IF(T19="","",U19) | W19: =IF(T19="","",RANK(V19,$V$9:$V$20,1)) | X19: -
B20: =IF(MAX($W$9:$W$20)<=11,"",VLOOKUP(B19+1,$W$9:$X$20,1,FALSE)) | C20: =IF(MAX($W$9:$W$20)<=11,"",VLOOKUP(B19+1,$W$9:$X$20,2,FALSE)) | O20: FALSE | P20: =IF(O20=TRUE,1,0) | Q20: FALSE | R20: =IF(Q20=TRUE,1,0) | U20: 12 | V20: =+IF(T20="","",U20) | W20: =IF(T20="","",RANK(V20,$V$9:$V$20,1)) | X20: -

Sheet Heures BE
A1: Tâches BE | B1: Heures estimées | C1: Heures Vendues
A2: LBE | B2: 2
A3: Nomenclature | B3: 2
A4: Plans TUT | B4: 8
A5: Plans isométriques | B5: 12
A6: Tableau de débits | B6: 1
A7: Plans GC | B7: 0
A8: Plans de manchettes délardées | B8: 0.5
A9: Plans de montage d'épreuve/séchage | B9: 1
A10: Plans de sertissage | B10: 0.5
A11: Plans Levage | B11: 0
A12: GDER | B12: 4
A13: Cahier de soudage avec validation pré-soudage | B13: 8
... A18: Dossier de fin d'affaire | B18: 4
A20: TOTAL | B20: =SUM(B2:B18) | C20: 74
A22: Objectif | B22: 60

Sheet Référentiel (A COMPLETER)
B2: Table Clients (référentiel)
B4: N° Affaire (clé) | C4: Code Client | D4: Nom Client | E4: Code Responsable ARTIS | F4: Nom Responsable ARTIS
B5: 2026-AF095 | C5: A COMPLETER | D5: NATRAN | E5: A COMPLETER | F5: AYTE

Sheet Référentiel réglem. (DRAFT)
B2: Référentiel réglementaire par type de livrable — brouillon à valider avec toi
B4: Type de livrable | C4: Référence réglementaire / texte type | D4: Condition d'application | E4: Source (à préciser)
B5: Nomenclature | D5: A COMPLETER | E5: A COMPLETER
B6: Plans isométriques manuel | D6: A COMPLETER | E6: A COMPLETER
B7: Résa 80% | D7: A COMPLETER | E7: A COMPLETER
B8: Plans 3D | D8: A COMPLETER | E8: A COMPLETER
B9: Plans TUT | D9: A COMPLETER | E9: A COMPLETER
B10: Résa 100% | D10: A COMPLETER | E10: A COMPLETER
B11: Plans isométriques - Repérage pièces | D11: A COMPLETER | E11: A COMPLETER
B12: Plans isométriques - Repérage soudures | D12: A COMPLETER | E12: A COMPLETER
B13: Tableau de débits | D13: A COMPLETER | E13: A COMPLETER
B14: Plans GC | D14: A COMPLETER | E14: A COMPLETER
B15: Plans de manchettes délardées | D15: A COMPLETER | E15: A COMPLETER
B16: Plans de châssis | D16: A COMPLETER | E16: A COMPLETER
... B31: DMOS / QMOS /QS | D31: A COMPLETER | E31: A COMPLETER
B32: Dossier d'épreuve selon DESP 2014/68/UE | C32: Directive 2014/68/UE - DESP (texte cité dans l'intitulé du livrable) | D32: A COMPLETER | E32: A COMPLETER
B33: Dossier d'épreuve selon A.M du 05/03/2014 | C33: Arrêté Ministériel du 05/03/2014 (texte cité dans l'intitulé du livrable) | D33: A COMPLETER | E33: A COMPLETER
B34: Dossier de Fabrication selon Art.4.3 | D34: A COMPLETER | E34: A COMPLETER
B35: Relevé Epaisseur Manchette délardée | D35: A COMPLETER | E35: A COMPLETER
B36: PV Cintrage | D36: A COMPLETER | E36: A COMPLETER
B37: PV Relevés paramètres de soudage | D37: A COMPLETER | E37: A COMPLETER
B38: Carnet de soudures | D38: A COMPLETER | E38: A COMPLETER
B39: Dossier de fin d'affaire | D39: A COMPLETER | E39: A COMPLETER

Sheet Mapping Heures BE (DRAFT)
B2: Correspondance Livrable (Actions) -> Tâche BE (Heures BE) — brouillon à valider
B4: Livrable (Actions - Liste des livrables) | C4: Tâche BE correspondante (Heures BE) | D4: Coché sur cette affaire | E4: Heures estimées
B5: Nomenclature | C5: Nomenclature | D5: =IFERROR(INDEX('Actions - Liste des livrables'!$I$11:$I$46,MATCH(B5,'Actions - Liste des livrables'!$M$11:$M$46,0)),"") | E5: =IFERROR(IF(D5="x",INDEX('Heures BE'!$B$2:$B$18,MATCH(C5,'Heures BE'!$A$2:$A$18,0)),0),0)
B6: Plans TUT | C6: Plans TUT | D6: =IFERROR(INDEX('Actions - Liste des livrables'!$I$11:$I$46,MATCH(B6,'Actions - Liste des livrables'!$M$11:$M$46,0)),"") | E6: =IFERROR(IF(D6="x",INDEX('Heures BE'!$B$2:$B$18,MATCH(C6,'Heures BE'!$A$2:$A$18,0)),0),0)
B7: Plans isométriques - Repérage pièces | C7: Plans isométriques | D7: =IFERROR(INDEX('Actions - Liste des livrables'!$I$11:$I$46,MATCH(B7,'Actions - Liste des livrables'!$M$11:$M$46,0)),"") | E7: =IFERROR(IF(D7="x",INDEX('Heures BE'!$B$2:$B$18,MATCH(C7,'Heures BE'!$A$2:$A$18,0)),0),0)
B8: Plans isométriques - Repérage soudures | C8: Plans isométriques | D8: =IFERROR(INDEX('Actions - Liste des livrables'!$I$11:$I$46,MATCH(B8,'Actions - Liste des livrables'!$M$11:$M$46,0)),"") | E8: =IFERROR(IF(D8="x",INDEX('Heures BE'!$B$2:$B$18,MATCH(C8,'Heures BE'!$A$2:$A$18,0)),0),0)
B9: Plans isométriques - Repérage brides et appareils | C9: Plans isométriques | D9: =IFERROR(INDEX('Actions - Liste des livrables'!$I$11:$I$46,MATCH(B9,'Actions - Liste des livrables'!$M$11:$M$46,0)),"") | E9: =IFERROR(IF(D9="x",INDEX('Heures BE'!$B$2:$B$18,MATCH(C9,'Heures BE'!$A$2:$A$18,0)),0),0)
B10: Tableau de débits | C10: Tableau de débits | D10: =IFERROR(INDEX('Actions - Liste des livrables'!$I$11:$I$46,MATCH(B10,'Actions - Liste des livrables'!$M$11:$M$46,0)),"") | E10: =IFERROR(IF(D10="x",INDEX('Heures BE'!$B$2:$B$18,MATCH(C10,'Heures BE'!$A$2:$A$18,0)),0),0)
B11: Plans GC | C11: Plans GC | D11: =IFERROR(INDEX('Actions - Liste des livrables'!$I$11:$I$46,MATCH(B11,'Actions - Liste des livrables'!$M$11:$M$46,0)),"") | E11: =IFERROR(IF(D11="x",INDEX('Heures BE'!$B$2:$B$18,MATCH(C11,'Heures BE'!$A$2:$A$18,0)),0),0)
B12: Plans de manchettes délardées | C12: Plans de manchettes délardées | D12: =IFERROR(INDEX('Actions - Liste des livrables'!$I$11:$I$46,MATCH(B12,'Actions - Liste des livrables'!$M$11:$M$46,0)),"") | E12: =IFERROR(IF(D12="x",INDEX('Heures BE'!$B$2:$B$18,MATCH(C12,'Heures BE'!$A$2:$A$18,0)),0),0)
B13: Plans de montage d'épreuve/séchage | C13: Plans de montage d'épreuve/séchage | D13: =IFERROR(INDEX('Actions - Liste des livrables'!$I$11:$I$46,MATCH(B13,'Actions - Liste des livrables'!$M$11:$M$46,0)),"") | E13: =IFERROR(IF(D13="x",INDEX('Heures BE'!$B$2:$B$18,MATCH(C13,'Heures BE'!$A$2:$A$18,0)),0),0)
B14: Plans de sertissage | C14: Plans de sertissage | D14: =IFERROR(INDEX('Actions - Liste des livrables'!$I$11:$I$46,MATCH(B14,'Actions - Liste des livrables'!$M$11:$M$46,0)),"") | E14: =IFERROR(IF(D14="x",INDEX('Heures BE'!$B$2:$B$18,MATCH(C14,'Heures BE'!$A$2:$A$18,0)),0),0)
B15: Plans Levage | C15: Plans Levage | D15: =IFERROR(INDEX('Actions - Liste des livrables'!$I$11:$I$46,MATCH(B15,'Actions - Liste des livrables'!$M$11:$M$46,0)),"") | E15: =IFERROR(IF(D15="x",INDEX('Heures BE'!$B$2:$B$18,MATCH(C15,'Heures BE'!$A$2:$A$18,0)),0),0)
B16: Plans enrobage / Peinture | C16: Plans enrobage / Peinture | D16: =IFERROR(INDEX('Actions - Liste des livrables'!$I$11:$I$46,MATCH(B16,'Actions - Liste des livrables'!$M$11:$M$46,0)),"") | E16: =IFERROR(IF(D16="x",INDEX('Heures BE'!$B$2:$B$18,MATCH(C16,'Heures BE'!$A$2:$A$18,0)),0),0)
... B26: Dossier de fin d'affaire | C26: Dossier de fin d'affaire | D26: =IFERROR(INDEX('Actions - Liste des livrables'!$I$11:$I$46,MATCH(B26,'Actions - Liste des livrables'!$M$11:$M$46,0)),"") | E26: =IFERROR(IF(D26="x",INDEX('Heures BE'!$B$2:$B$18,MATCH(C26,'Heures BE'!$A$2:$A$18,0)),0),0)
B28: TOTAL auto (selon coches) - a comparer avec Heures BE!B20 | E28: =SUM(E5:E26)
